Watching for file changes with StatReloader
Watching for file changes with StatReloader
C:\Users\KalyaginDN\Desktop\R4C\robots\views.py changed, reloading.
Watching for file changes with StatReloader
Robot created successfully.
Robot created successfully.
Robot created successfully.
Watching for file changes with StatReloader
Robot created successfully.
C:\Users\KalyaginDN\Desktop\R4C\R4C\settings.py changed, reloading.
Watching for file changes with StatReloader
Robot created successfully.
C:\Users\KalyaginDN\Desktop\R4C\R4C\settings.py changed, reloading.
Watching for file changes with StatReloader
Internal Server Error: /create_robot/
Traceback (most recent call last):
  File "C:\Users\KalyaginDN\Desktop\R4C\venv\lib\site-packages\django\core\handlers\exception.py", line 34, in inner
    response = get_response(request)
  File "C:\Users\KalyaginDN\Desktop\R4C\venv\lib\site-packages\django\core\handlers\base.py", line 115, in _get_response
    response = self.process_exception_by_middleware(e, request)
  File "C:\Users\KalyaginDN\Desktop\R4C\venv\lib\site-packages\django\core\handlers\base.py", line 113, in _get_response
    response = wrapped_callback(request, *callback_args, **callback_kwargs)
  File "C:\Users\KalyaginDN\Desktop\R4C\venv\lib\site-packages\django\views\decorators\csrf.py", line 54, in wrapped_view
    return view_func(*args, **kwargs)
  File "C:\Users\KalyaginDN\Desktop\R4C\robots\views.py", line 26, in create_robot
    robot.save()
  File "C:\Users\KalyaginDN\Desktop\R4C\venv\lib\site-packages\django\db\models\base.py", line 745, in save
    self.save_base(using=using, force_insert=force_insert,
  File "C:\Users\KalyaginDN\Desktop\R4C\venv\lib\site-packages\django\db\models\base.py", line 793, in save_base
    post_save.send(
  File "C:\Users\KalyaginDN\Desktop\R4C\venv\lib\site-packages\django\dispatch\dispatcher.py", line 173, in send
    return [
  File "C:\Users\KalyaginDN\Desktop\R4C\venv\lib\site-packages\django\dispatch\dispatcher.py", line 174, in <listcomp>
    (receiver, receiver(signal=self, sender=sender, **named))
  File "C:\Users\KalyaginDN\Desktop\R4C\robots\models.py", line 22, in robot_create
    Robot.objects.create(robots=instance)
  File "C:\Users\KalyaginDN\Desktop\R4C\venv\lib\site-packages\django\db\models\manager.py", line 82, in manager_method
    return getattr(self.get_queryset(), name)(*args, **kwargs)
  File "C:\Users\KalyaginDN\Desktop\R4C\venv\lib\site-packages\django\db\models\query.py", line 431, in create
    obj = self.model(**kwargs)
  File "C:\Users\KalyaginDN\Desktop\R4C\venv\lib\site-packages\django\db\models\base.py", line 500, in __init__
    raise TypeError("%s() got an unexpected keyword argument '%s'" % (cls.__name__, kwarg))
TypeError: Robot() got an unexpected keyword argument 'robots'
C:\Users\KalyaginDN\Desktop\R4C\robots\models.py changed, reloading.
Watching for file changes with StatReloader
Internal Server Error: /create_robot/
Traceback (most recent call last):
  File "C:\Users\KalyaginDN\Desktop\R4C\venv\lib\site-packages\django\core\handlers\exception.py", line 34, in inner
    response = get_response(request)
  File "C:\Users\KalyaginDN\Desktop\R4C\venv\lib\site-packages\django\core\handlers\base.py", line 115, in _get_response
    response = self.process_exception_by_middleware(e, request)
  File "C:\Users\KalyaginDN\Desktop\R4C\venv\lib\site-packages\django\core\handlers\base.py", line 113, in _get_response
    response = wrapped_callback(request, *callback_args, **callback_kwargs)
  File "C:\Users\KalyaginDN\Desktop\R4C\venv\lib\site-packages\django\views\decorators\csrf.py", line 54, in wrapped_view
    return view_func(*args, **kwargs)
  File "C:\Users\KalyaginDN\Desktop\R4C\robots\views.py", line 26, in create_robot
    robot.save()
  File "C:\Users\KalyaginDN\Desktop\R4C\venv\lib\site-packages\django\db\models\base.py", line 745, in save
    self.save_base(using=using, force_insert=force_insert,
  File "C:\Users\KalyaginDN\Desktop\R4C\venv\lib\site-packages\django\db\models\base.py", line 793, in save_base
    post_save.send(
  File "C:\Users\KalyaginDN\Desktop\R4C\venv\lib\site-packages\django\dispatch\dispatcher.py", line 173, in send
    return [
  File "C:\Users\KalyaginDN\Desktop\R4C\venv\lib\site-packages\django\dispatch\dispatcher.py", line 174, in <listcomp>
    (receiver, receiver(signal=self, sender=sender, **named))
  File "C:\Users\KalyaginDN\Desktop\R4C\robots\models.py", line 22, in robot_create
    Robot.objects.create(robots=instance)
  File "C:\Users\KalyaginDN\Desktop\R4C\venv\lib\site-packages\django\db\models\manager.py", line 82, in manager_method
    return getattr(self.get_queryset(), name)(*args, **kwargs)
  File "C:\Users\KalyaginDN\Desktop\R4C\venv\lib\site-packages\django\db\models\query.py", line 431, in create
    obj = self.model(**kwargs)
  File "C:\Users\KalyaginDN\Desktop\R4C\venv\lib\site-packages\django\db\models\base.py", line 500, in __init__
    raise TypeError("%s() got an unexpected keyword argument '%s'" % (cls.__name__, kwarg))
TypeError: Robot() got an unexpected keyword argument 'robots'
C:\Users\KalyaginDN\Desktop\R4C\robots\models.py changed, reloading.
Watching for file changes with StatReloader
Internal Server Error: /create_robot/
Traceback (most recent call last):
  File "C:\Users\KalyaginDN\Desktop\R4C\venv\lib\site-packages\django\core\handlers\exception.py", line 34, in inner
    response = get_response(request)
  File "C:\Users\KalyaginDN\Desktop\R4C\venv\lib\site-packages\django\core\handlers\base.py", line 115, in _get_response
    response = self.process_exception_by_middleware(e, request)
  File "C:\Users\KalyaginDN\Desktop\R4C\venv\lib\site-packages\django\core\handlers\base.py", line 113, in _get_response
    response = wrapped_callback(request, *callback_args, **callback_kwargs)
  File "C:\Users\KalyaginDN\Desktop\R4C\venv\lib\site-packages\django\views\decorators\csrf.py", line 54, in wrapped_view
    return view_func(*args, **kwargs)
  File "C:\Users\KalyaginDN\Desktop\R4C\robots\views.py", line 26, in create_robot
    robot.save()
  File "C:\Users\KalyaginDN\Desktop\R4C\venv\lib\site-packages\django\db\models\base.py", line 745, in save
    self.save_base(using=using, force_insert=force_insert,
  File "C:\Users\KalyaginDN\Desktop\R4C\venv\lib\site-packages\django\db\models\base.py", line 793, in save_base
    post_save.send(
  File "C:\Users\KalyaginDN\Desktop\R4C\venv\lib\site-packages\django\dispatch\dispatcher.py", line 173, in send
    return [
  File "C:\Users\KalyaginDN\Desktop\R4C\venv\lib\site-packages\django\dispatch\dispatcher.py", line 174, in <listcomp>
    (receiver, receiver(signal=self, sender=sender, **named))
  File "C:\Users\KalyaginDN\Desktop\R4C\robots\models.py", line 22, in robot_create
    Robot.objects.create(robots=instance)
  File "C:\Users\KalyaginDN\Desktop\R4C\venv\lib\site-packages\django\db\models\manager.py", line 82, in manager_method
    return getattr(self.get_queryset(), name)(*args, **kwargs)
  File "C:\Users\KalyaginDN\Desktop\R4C\venv\lib\site-packages\django\db\models\query.py", line 431, in create
    obj = self.model(**kwargs)
  File "C:\Users\KalyaginDN\Desktop\R4C\venv\lib\site-packages\django\db\models\base.py", line 500, in __init__
    raise TypeError("%s() got an unexpected keyword argument '%s'" % (cls.__name__, kwarg))
TypeError: Robot() got an unexpected keyword argument 'robots'
C:\Users\KalyaginDN\Desktop\R4C\robots\models.py changed, reloading.
Watching for file changes with StatReloader
C:\Users\KalyaginDN\Desktop\R4C\robots\signals.py changed, reloading.
Watching for file changes with StatReloader
Robot created successfully.
C:\Users\KalyaginDN\Desktop\R4C\robots\views.py changed, reloading.
Watching for file changes with StatReloader
C:\Users\KalyaginDN\Desktop\R4C\robots\models.py changed, reloading.
Watching for file changes with StatReloader
Watching for file changes with StatReloader
Watching for file changes with StatReloader
C:\Users\KalyaginDN\Desktop\R4C\R4C\settings.py changed, reloading.
Watching for file changes with StatReloader
Watching for file changes with StatReloader
C:\Users\KalyaginDN\Desktop\R4C\R4C\settings.py changed, reloading.
Watching for file changes with StatReloader
C:\Users\KalyaginDN\Desktop\R4C\robots\models.py changed, reloading.
Watching for file changes with StatReloader
C:\Users\KalyaginDN\Desktop\R4C\robots\models.py changed, reloading.
Watching for file changes with StatReloader
Watching for file changes with StatReloader
Watching for file changes with StatReloader
Watching for file changes with StatReloader
C:\Users\KalyaginDN\Desktop\R4C\R4C\settings.py changed, reloading.
Watching for file changes with StatReloader
C:\Users\KalyaginDN\Desktop\R4C\R4C\settings.py changed, reloading.
Watching for file changes with StatReloader
Robot created successfully.
C:\Users\KalyaginDN\Desktop\R4C\robots\apps.py changed, reloading.
Watching for file changes with StatReloader
Robot created successfully.
C:\Users\KalyaginDN\Desktop\R4C\robots\signals.py changed, reloading.
Watching for file changes with StatReloader
Robot created successfully.
C:\Users\KalyaginDN\Desktop\R4C\robots\signals.py changed, reloading.
Watching for file changes with StatReloader
Robot created successfully.
C:\Users\KalyaginDN\Desktop\R4C\robots\apps.py changed, reloading.
Watching for file changes with StatReloader
C:\Users\KalyaginDN\Desktop\R4C\robots\apps.py changed, reloading.
Watching for file changes with StatReloader
C:\Users\KalyaginDN\Desktop\R4C\robots\signals.py changed, reloading.
Watching for file changes with StatReloader
C:\Users\KalyaginDN\Desktop\R4C\robots\signals.py changed, reloading.
Watching for file changes with StatReloader
Robot created successfully.
C:\Users\KalyaginDN\Desktop\R4C\robots\signals.py changed, reloading.
Watching for file changes with StatReloader
C:\Users\KalyaginDN\Desktop\R4C\robots\signals.py changed, reloading.
Watching for file changes with StatReloader
Robot created successfully.
Internal Server Error: /create_robot/
Traceback (most recent call last):
  File "C:\Users\KalyaginDN\Desktop\R4C\venv\lib\site-packages\django\core\handlers\exception.py", line 34, in inner
    response = get_response(request)
  File "C:\Users\KalyaginDN\Desktop\R4C\venv\lib\site-packages\django\core\handlers\base.py", line 115, in _get_response
    response = self.process_exception_by_middleware(e, request)
  File "C:\Users\KalyaginDN\Desktop\R4C\venv\lib\site-packages\django\core\handlers\base.py", line 113, in _get_response
    response = wrapped_callback(request, *callback_args, **callback_kwargs)
  File "C:\Users\KalyaginDN\Desktop\R4C\venv\lib\site-packages\django\views\decorators\csrf.py", line 54, in wrapped_view
    return view_func(*args, **kwargs)
  File "C:\Users\KalyaginDN\Desktop\R4C\robots\views.py", line 25, in create_robot
    robot.save()
  File "C:\Users\KalyaginDN\Desktop\R4C\venv\lib\site-packages\django\db\models\base.py", line 745, in save
    self.save_base(using=using, force_insert=force_insert,
  File "C:\Users\KalyaginDN\Desktop\R4C\venv\lib\site-packages\django\db\models\base.py", line 793, in save_base
    post_save.send(
  File "C:\Users\KalyaginDN\Desktop\R4C\venv\lib\site-packages\django\dispatch\dispatcher.py", line 173, in send
    return [
  File "C:\Users\KalyaginDN\Desktop\R4C\venv\lib\site-packages\django\dispatch\dispatcher.py", line 174, in <listcomp>
    (receiver, receiver(signal=self, sender=sender, **named))
  File "C:\Users\KalyaginDN\Desktop\R4C\robots\signals.py", line 14, in robot_create
    print(last_object('model'))
TypeError: 'Robot' object is not callable
C:\Users\KalyaginDN\Desktop\R4C\robots\signals.py changed, reloading.
Watching for file changes with StatReloader
Robot created successfully.
Internal Server Error: /create_robot/
Traceback (most recent call last):
  File "C:\Users\KalyaginDN\Desktop\R4C\venv\lib\site-packages\django\core\handlers\exception.py", line 34, in inner
    response = get_response(request)
  File "C:\Users\KalyaginDN\Desktop\R4C\venv\lib\site-packages\django\core\handlers\base.py", line 115, in _get_response
    response = self.process_exception_by_middleware(e, request)
  File "C:\Users\KalyaginDN\Desktop\R4C\venv\lib\site-packages\django\core\handlers\base.py", line 113, in _get_response
    response = wrapped_callback(request, *callback_args, **callback_kwargs)
  File "C:\Users\KalyaginDN\Desktop\R4C\venv\lib\site-packages\django\views\decorators\csrf.py", line 54, in wrapped_view
    return view_func(*args, **kwargs)
  File "C:\Users\KalyaginDN\Desktop\R4C\robots\views.py", line 25, in create_robot
    robot.save()
  File "C:\Users\KalyaginDN\Desktop\R4C\venv\lib\site-packages\django\db\models\base.py", line 745, in save
    self.save_base(using=using, force_insert=force_insert,
  File "C:\Users\KalyaginDN\Desktop\R4C\venv\lib\site-packages\django\db\models\base.py", line 793, in save_base
    post_save.send(
  File "C:\Users\KalyaginDN\Desktop\R4C\venv\lib\site-packages\django\dispatch\dispatcher.py", line 173, in send
    return [
  File "C:\Users\KalyaginDN\Desktop\R4C\venv\lib\site-packages\django\dispatch\dispatcher.py", line 174, in <listcomp>
    (receiver, receiver(signal=self, sender=sender, **named))
  File "C:\Users\KalyaginDN\Desktop\R4C\robots\signals.py", line 14, in robot_create
    print(last_object.values('model'))
AttributeError: 'Robot' object has no attribute 'values'
C:\Users\KalyaginDN\Desktop\R4C\robots\signals.py changed, reloading.
Watching for file changes with StatReloader
C:\Users\KalyaginDN\Desktop\R4C\robots\signals.py changed, reloading.
Watching for file changes with StatReloader
Robot created successfully.
C:\Users\KalyaginDN\Desktop\R4C\robots\signals.py changed, reloading.
Watching for file changes with StatReloader
Robot created successfully.
C:\Users\KalyaginDN\Desktop\R4C\robots\signals.py changed, reloading.
Watching for file changes with StatReloader
Robot created successfully.
C:\Users\KalyaginDN\Desktop\R4C\robots\signals.py changed, reloading.
Watching for file changes with StatReloader
Robot created successfully.
Internal Server Error: /create_robot/
Traceback (most recent call last):
  File "C:\Users\KalyaginDN\Desktop\R4C\venv\lib\site-packages\django\core\handlers\exception.py", line 34, in inner
    response = get_response(request)
  File "C:\Users\KalyaginDN\Desktop\R4C\venv\lib\site-packages\django\core\handlers\base.py", line 115, in _get_response
    response = self.process_exception_by_middleware(e, request)
  File "C:\Users\KalyaginDN\Desktop\R4C\venv\lib\site-packages\django\core\handlers\base.py", line 113, in _get_response
    response = wrapped_callback(request, *callback_args, **callback_kwargs)
  File "C:\Users\KalyaginDN\Desktop\R4C\venv\lib\site-packages\django\views\decorators\csrf.py", line 54, in wrapped_view
    return view_func(*args, **kwargs)
  File "C:\Users\KalyaginDN\Desktop\R4C\robots\views.py", line 25, in create_robot
    robot.save()
  File "C:\Users\KalyaginDN\Desktop\R4C\venv\lib\site-packages\django\db\models\base.py", line 745, in save
    self.save_base(using=using, force_insert=force_insert,
  File "C:\Users\KalyaginDN\Desktop\R4C\venv\lib\site-packages\django\db\models\base.py", line 793, in save_base
    post_save.send(
  File "C:\Users\KalyaginDN\Desktop\R4C\venv\lib\site-packages\django\dispatch\dispatcher.py", line 173, in send
    return [
  File "C:\Users\KalyaginDN\Desktop\R4C\venv\lib\site-packages\django\dispatch\dispatcher.py", line 174, in <listcomp>
    (receiver, receiver(signal=self, sender=sender, **named))
  File "C:\Users\KalyaginDN\Desktop\R4C\robots\signals.py", line 16, in robot_create
    print(created.model)
AttributeError: 'bool' object has no attribute 'model'
C:\Users\KalyaginDN\Desktop\R4C\robots\signals.py changed, reloading.
Watching for file changes with StatReloader
Robot created successfully.
C:\Users\KalyaginDN\Desktop\R4C\robots\signals.py changed, reloading.
Watching for file changes with StatReloader
Robot created successfully.
C:\Users\KalyaginDN\Desktop\R4C\robots\signals.py changed, reloading.
Watching for file changes with StatReloader
C:\Users\KalyaginDN\Desktop\R4C\robots\signals.py changed, reloading.
Watching for file changes with StatReloader
Robot created successfully.
C:\Users\KalyaginDN\Desktop\R4C\robots\signals.py changed, reloading.
Watching for file changes with StatReloader
Robot created successfully.
C:\Users\KalyaginDN\Desktop\R4C\robots\signals.py changed, reloading.
Watching for file changes with StatReloader
Robot created successfully.
C:\Users\KalyaginDN\Desktop\R4C\robots\signals.py changed, reloading.
Watching for file changes with StatReloader
Robot created successfully.
C:\Users\KalyaginDN\Desktop\R4C\robots\signals.py changed, reloading.
Watching for file changes with StatReloader
Robot created successfully.
C:\Users\KalyaginDN\Desktop\R4C\robots\signals.py changed, reloading.
Watching for file changes with StatReloader
Robot created successfully.
C:\Users\KalyaginDN\Desktop\R4C\robots\signals.py changed, reloading.
Watching for file changes with StatReloader
Robot created successfully.
Internal Server Error: /create_robot/
Traceback (most recent call last):
  File "C:\Users\KalyaginDN\Desktop\R4C\venv\lib\site-packages\django\core\handlers\exception.py", line 34, in inner
    response = get_response(request)
  File "C:\Users\KalyaginDN\Desktop\R4C\venv\lib\site-packages\django\core\handlers\base.py", line 115, in _get_response
    response = self.process_exception_by_middleware(e, request)
  File "C:\Users\KalyaginDN\Desktop\R4C\venv\lib\site-packages\django\core\handlers\base.py", line 113, in _get_response
    response = wrapped_callback(request, *callback_args, **callback_kwargs)
  File "C:\Users\KalyaginDN\Desktop\R4C\venv\lib\site-packages\django\views\decorators\csrf.py", line 54, in wrapped_view
    return view_func(*args, **kwargs)
  File "C:\Users\KalyaginDN\Desktop\R4C\robots\views.py", line 25, in create_robot
    robot.save()
  File "C:\Users\KalyaginDN\Desktop\R4C\venv\lib\site-packages\django\db\models\base.py", line 745, in save
    self.save_base(using=using, force_insert=force_insert,
  File "C:\Users\KalyaginDN\Desktop\R4C\venv\lib\site-packages\django\db\models\base.py", line 793, in save_base
    post_save.send(
  File "C:\Users\KalyaginDN\Desktop\R4C\venv\lib\site-packages\django\dispatch\dispatcher.py", line 173, in send
    return [
  File "C:\Users\KalyaginDN\Desktop\R4C\venv\lib\site-packages\django\dispatch\dispatcher.py", line 174, in <listcomp>
    (receiver, receiver(signal=self, sender=sender, **named))
  File "C:\Users\KalyaginDN\Desktop\R4C\robots\signals.py", line 16, in robot_create
    orders = Order.objects.filter(
  File "C:\Users\KalyaginDN\Desktop\R4C\venv\lib\site-packages\django\db\models\query.py", line 314, in __getitem__
    return qs._result_cache[0]
IndexError: list index out of range
Robot created successfully.
Internal Server Error: /create_robot/
Traceback (most recent call last):
  File "C:\Users\KalyaginDN\Desktop\R4C\venv\lib\site-packages\django\core\handlers\exception.py", line 34, in inner
    response = get_response(request)
  File "C:\Users\KalyaginDN\Desktop\R4C\venv\lib\site-packages\django\core\handlers\base.py", line 115, in _get_response
    response = self.process_exception_by_middleware(e, request)
  File "C:\Users\KalyaginDN\Desktop\R4C\venv\lib\site-packages\django\core\handlers\base.py", line 113, in _get_response
    response = wrapped_callback(request, *callback_args, **callback_kwargs)
  File "C:\Users\KalyaginDN\Desktop\R4C\venv\lib\site-packages\django\views\decorators\csrf.py", line 54, in wrapped_view
    return view_func(*args, **kwargs)
  File "C:\Users\KalyaginDN\Desktop\R4C\robots\views.py", line 25, in create_robot
    robot.save()
  File "C:\Users\KalyaginDN\Desktop\R4C\venv\lib\site-packages\django\db\models\base.py", line 745, in save
    self.save_base(using=using, force_insert=force_insert,
  File "C:\Users\KalyaginDN\Desktop\R4C\venv\lib\site-packages\django\db\models\base.py", line 793, in save_base
    post_save.send(
  File "C:\Users\KalyaginDN\Desktop\R4C\venv\lib\site-packages\django\dispatch\dispatcher.py", line 173, in send
    return [
  File "C:\Users\KalyaginDN\Desktop\R4C\venv\lib\site-packages\django\dispatch\dispatcher.py", line 174, in <listcomp>
    (receiver, receiver(signal=self, sender=sender, **named))
  File "C:\Users\KalyaginDN\Desktop\R4C\robots\signals.py", line 16, in robot_create
    orders = Order.objects.filter(
  File "C:\Users\KalyaginDN\Desktop\R4C\venv\lib\site-packages\django\db\models\query.py", line 314, in __getitem__
    return qs._result_cache[0]
IndexError: list index out of range
C:\Users\KalyaginDN\Desktop\R4C\robots\signals.py changed, reloading.
Watching for file changes with StatReloader
C:\Users\KalyaginDN\Desktop\R4C\robots\signals.py changed, reloading.
Watching for file changes with StatReloader
Robot created successfully.
C:\Users\KalyaginDN\Desktop\R4C\robots\signals.py changed, reloading.
Watching for file changes with StatReloader
Robot created successfully.
C:\Users\KalyaginDN\Desktop\R4C\robots\signals.py changed, reloading.
Watching for file changes with StatReloader
Robot created successfully.
Robot created successfully.
C:\Users\KalyaginDN\Desktop\R4C\robots\signals.py changed, reloading.
Watching for file changes with StatReloader
Robot created successfully.
Robot created successfully.
C:\Users\KalyaginDN\Desktop\R4C\robots\signals.py changed, reloading.
Watching for file changes with StatReloader
C:\Users\KalyaginDN\Desktop\R4C\customers\models.py changed, reloading.
Watching for file changes with StatReloader
C:\Users\KalyaginDN\Desktop\R4C\robots\signals.py changed, reloading.
Watching for file changes with StatReloader
C:\Users\KalyaginDN\Desktop\R4C\robots\signals.py changed, reloading.
Watching for file changes with StatReloader
C:\Users\KalyaginDN\Desktop\R4C\customers\models.py changed, reloading.
Watching for file changes with StatReloader
C:\Users\KalyaginDN\Desktop\R4C\orders\views.py changed, reloading.
Watching for file changes with StatReloader
Watching for file changes with StatReloader
C:\Users\KalyaginDN\Desktop\R4C\robots\views.py changed, reloading.
Watching for file changes with StatReloader
Not Found: /export_to_excel
Robot created successfully.
Internal Server Error: /create_robot/
Traceback (most recent call last):
  File "C:\Users\KalyaginDN\Desktop\R4C\venv\lib\site-packages\django\core\handlers\exception.py", line 34, in inner
    response = get_response(request)
  File "C:\Users\KalyaginDN\Desktop\R4C\venv\lib\site-packages\django\core\handlers\base.py", line 115, in _get_response
    response = self.process_exception_by_middleware(e, request)
  File "C:\Users\KalyaginDN\Desktop\R4C\venv\lib\site-packages\django\core\handlers\base.py", line 113, in _get_response
    response = wrapped_callback(request, *callback_args, **callback_kwargs)
  File "C:\Users\KalyaginDN\Desktop\R4C\venv\lib\site-packages\django\views\decorators\csrf.py", line 54, in wrapped_view
    return view_func(*args, **kwargs)
  File "C:\Users\KalyaginDN\Desktop\R4C\robots\views.py", line 25, in create_robot
    robot.save()
  File "C:\Users\KalyaginDN\Desktop\R4C\venv\lib\site-packages\django\db\models\base.py", line 745, in save
    self.save_base(using=using, force_insert=force_insert,
  File "C:\Users\KalyaginDN\Desktop\R4C\venv\lib\site-packages\django\db\models\base.py", line 793, in save_base
    post_save.send(
  File "C:\Users\KalyaginDN\Desktop\R4C\venv\lib\site-packages\django\dispatch\dispatcher.py", line 173, in send
    return [
  File "C:\Users\KalyaginDN\Desktop\R4C\venv\lib\site-packages\django\dispatch\dispatcher.py", line 174, in <listcomp>
    (receiver, receiver(signal=self, sender=sender, **named))
  File "C:\Users\KalyaginDN\Desktop\R4C\robots\signals.py", line 23, in robot_create
    order = orders.first()
  File "C:\Users\KalyaginDN\Desktop\R4C\venv\lib\site-packages\django\db\models\query.py", line 664, in first
    for obj in (self if self.ordered else self.order_by('pk'))[:1]:
  File "C:\Users\KalyaginDN\Desktop\R4C\venv\lib\site-packages\django\db\models\query.py", line 1085, in order_by
    assert not self.query.is_sliced, \
AssertionError: Cannot reorder a query once a slice has been taken.
Robot created successfully.
No matching orders found.
Watching for file changes with StatReloader
Robot created successfully.
No matching orders found.
Watching for file changes with StatReloader
C:\Users\KalyaginDN\Desktop\R4C\robots\views.py changed, reloading.
Watching for file changes with StatReloader
